Traceback (most recent call last):
  File "/Users/shakidi/opt/anaconda3/envs/myenv/lib/python3.9/site-packages/jupyter_cache/executors/utils.py", line 58, in single_nb_execution
    executenb(
  File "/Users/shakidi/opt/anaconda3/envs/myenv/lib/python3.9/site-packages/nbclient/client.py", line 1305, in execute
    return NotebookClient(nb=nb, resources=resources, km=km, **kwargs).execute()
  File "/Users/shakidi/opt/anaconda3/envs/myenv/lib/python3.9/site-packages/jupyter_core/utils/__init__.py", line 173, in wrapped
    return loop.run_until_complete(inner)
  File "/Users/shakidi/opt/anaconda3/envs/myenv/lib/python3.9/asyncio/base_events.py", line 647, in run_until_complete
    return future.result()
  File "/Users/shakidi/opt/anaconda3/envs/myenv/lib/python3.9/site-packages/nbclient/client.py", line 705, in async_execute
    await self.async_execute_cell(
  File "/Users/shakidi/opt/anaconda3/envs/myenv/lib/python3.9/site-packages/nbclient/client.py", line 1058, in async_execute_cell
    await self._check_raise_for_error(cell, cell_index, exec_reply)
  File "/Users/shakidi/opt/anaconda3/envs/myenv/lib/python3.9/site-packages/nbclient/client.py", line 914, in _check_raise_for_error
    raise CellExecutionError.from_cell_and_msg(cell, exec_reply_content)
nbclient.exceptions.CellExecutionError: An error occurred while executing the following cell:
------------------
projections = [ccrs.PlateCarree(),
               ccrs.Robinson(),
               ccrs.Mercator(),
               ccrs.Orthographic(),
               ccrs.InterruptedGoodeHomolosine()
              ]


for proj in projections:
    plt.figure()
    ax = plt.axes(projection=proj)
    ax.stock_img()
    ax.coastlines()
    ax.set_title(f'{type(proj)}')
------------------


[0;31m---------------------------------------------------------------------------[0m
[0;31mModuleNotFoundError[0m                       Traceback (most recent call last)
File [0;32m~/opt/anaconda3/envs/myenv/lib/python3.9/site-packages/cartopy/img_transform.py:14[0m
[1;32m     13[0m [38;5;28;01mtry[39;00m:
[0;32m---> 14[0m     [38;5;28;01mfrom[39;00m [38;5;21;01mpykdtree[39;00m[38;5;21;01m.[39;00m[38;5;21;01mkdtree[39;00m [38;5;28;01mimport[39;00m KDTree [38;5;28;01mas[39;00m _kdtreeClass
[1;32m     15[0m     _is_pykdtree [38;5;241m=[39m [38;5;28;01mTrue[39;00m

[0;31mModuleNotFoundError[0m: No module named 'pykdtree'

During handling of the above exception, another exception occurred:

[0;31mModuleNotFoundError[0m                       Traceback (most recent call last)
File [0;32m~/opt/anaconda3/envs/myenv/lib/python3.9/site-packages/cartopy/img_transform.py:18[0m
[1;32m     17[0m [38;5;28;01mtry[39;00m:
[0;32m---> 18[0m     [38;5;28;01mfrom[39;00m [38;5;21;01mscipy[39;00m[38;5;21;01m.[39;00m[38;5;21;01mspatial[39;00m [38;5;28;01mimport[39;00m cKDTree [38;5;28;01mas[39;00m _kdtreeClass
[1;32m     19[0m [38;5;28;01mexcept[39;00m [38;5;167;01mImportError[39;00m [38;5;28;01mas[39;00m e:

[0;31mModuleNotFoundError[0m: No module named 'scipy'

The above exception was the direct cause of the following exception:

[0;31mImportError[0m                               Traceback (most recent call last)
Cell [0;32mIn[9], line 12[0m
[1;32m     10[0m plt[38;5;241m.[39mfigure()
[1;32m     11[0m ax [38;5;241m=[39m plt[38;5;241m.[39maxes(projection[38;5;241m=[39mproj)
[0;32m---> 12[0m [43max[49m[38;5;241;43m.[39;49m[43mstock_img[49m[43m([49m[43m)[49m
[1;32m     13[0m ax[38;5;241m.[39mcoastlines()
[1;32m     14[0m ax[38;5;241m.[39mset_title([38;5;124mf[39m[38;5;124m'[39m[38;5;132;01m{[39;00m[38;5;28mtype[39m(proj)[38;5;132;01m}[39;00m[38;5;124m'[39m)

File [0;32m~/opt/anaconda3/envs/myenv/lib/python3.9/site-packages/cartopy/mpl/geoaxes.py:1007[0m, in [0;36mGeoAxes.stock_img[0;34m(self, name, **kwargs)[0m
[1;32m   1003[0m     source_proj [38;5;241m=[39m ccrs[38;5;241m.[39mPlateCarree()
[1;32m   1004[0m     fname [38;5;241m=[39m (config[[38;5;124m"[39m[38;5;124mrepo_data_dir[39m[38;5;124m"[39m] [38;5;241m/[39m [38;5;124m'[39m[38;5;124mraster[39m[38;5;124m'[39m [38;5;241m/[39m [38;5;124m'[39m[38;5;124mnatural_earth[39m[38;5;124m'[39m
[1;32m   1005[0m              [38;5;241m/[39m [38;5;124m'[39m[38;5;124m50-natural-earth-1-downsampled.png[39m[38;5;124m'[39m)
[0;32m-> 1007[0m     [38;5;28;01mreturn[39;00m [38;5;28;43mself[39;49m[38;5;241;43m.[39;49m[43mimshow[49m[43m([49m[43mimread[49m[43m([49m[43mfname[49m[43m)[49m[43m,[49m[43m [49m[43morigin[49m[38;5;241;43m=[39;49m[38;5;124;43m'[39;49m[38;5;124;43mupper[39;49m[38;5;124;43m'[39;49m[43m,[49m
[1;32m   1008[0m [43m                       [49m[43mtransform[49m[38;5;241;43m=[39;49m[43msource_proj[49m[43m,[49m
[1;32m   1009[0m [43m                       [49m[43mextent[49m[38;5;241;43m=[39;49m[43m[[49m[38;5;241;43m-[39;49m[38;5;241;43m180[39;49m[43m,[49m[43m [49m[38;5;241;43m180[39;49m[43m,[49m[43m [49m[38;5;241;43m-[39;49m[38;5;241;43m90[39;49m[43m,[49m[43m [49m[38;5;241;43m90[39;49m[43m][49m[43m,[49m
[1;32m   1010[0m [43m                       [49m[38;5;241;43m*[39;49m[38;5;241;43m*[39;49m[43mkwargs[49m[43m)[49m
[1;32m   1011[0m [38;5;28;01melse[39;00m:
[1;32m   1012[0m     [38;5;28;01mraise[39;00m [38;5;167;01mValueError[39;00m([38;5;124m'[39m[38;5;124mUnknown stock image [39m[38;5;132;01m%r[39;00m[38;5;124m.[39m[38;5;124m'[39m [38;5;241m%[39m name)

File [0;32m~/opt/anaconda3/envs/myenv/lib/python3.9/site-packages/cartopy/mpl/geoaxes.py:307[0m, in [0;36m_add_transform.<locals>.wrapper[0;34m(self, *args, **kwargs)[0m
[1;32m    302[0m     [38;5;28;01mraise[39;00m [38;5;167;01mValueError[39;00m([38;5;124mf[39m[38;5;124m'[39m[38;5;124mInvalid transform: Spherical [39m[38;5;132;01m{[39;00mfunc[38;5;241m.[39m[38;5;18m__name__[39m[38;5;132;01m}[39;00m[38;5;124m [39m[38;5;124m'[39m
[1;32m    303[0m                      [38;5;124m'[39m[38;5;124mis not supported - consider using [39m[38;5;124m'[39m
[1;32m    304[0m                      [38;5;124m'[39m[38;5;124mPlateCarree/RotatedPole.[39m[38;5;124m'[39m)
[1;32m    306[0m kwargs[[38;5;124m'[39m[38;5;124mtransform[39m[38;5;124m'[39m] [38;5;241m=[39m transform
[0;32m--> 307[0m [38;5;28;01mreturn[39;00m [43mfunc[49m[43m([49m[38;5;28;43mself[39;49m[43m,[49m[43m [49m[38;5;241;43m*[39;49m[43margs[49m[43m,[49m[43m [49m[38;5;241;43m*[39;49m[38;5;241;43m*[39;49m[43mkwargs[49m[43m)[49m

File [0;32m~/opt/anaconda3/envs/myenv/lib/python3.9/site-packages/cartopy/mpl/geoaxes.py:1312[0m, in [0;36mGeoAxes.imshow[0;34m(self, img, *args, **kwargs)[0m
[1;32m   1308[0m regrid_shape [38;5;241m=[39m [38;5;28mself[39m[38;5;241m.[39m_regrid_shape_aspect(regrid_shape,
[1;32m   1309[0m                                          target_extent)
[1;32m   1310[0m [38;5;66;03m# Lazy import because scipy/pykdtree in img_transform are only[39;00m
[1;32m   1311[0m [38;5;66;03m# optional dependencies[39;00m
[0;32m-> 1312[0m [38;5;28;01mfrom[39;00m [38;5;21;01mcartopy[39;00m[38;5;21;01m.[39;00m[38;5;21;01mimg_transform[39;00m [38;5;28;01mimport[39;00m warp_array
[1;32m   1313[0m original_extent [38;5;241m=[39m extent
[1;32m   1314[0m img, extent [38;5;241m=[39m warp_array(img,
[1;32m   1315[0m                          source_proj[38;5;241m=[39mtransform,
[1;32m   1316[0m                          source_extent[38;5;241m=[39moriginal_extent,
[0;32m   (...)[0m
[1;32m   1320[0m                          mask_extrapolated[38;5;241m=[39m[38;5;28;01mTrue[39;00m,
[1;32m   1321[0m                          )

File [0;32m~/opt/anaconda3/envs/myenv/lib/python3.9/site-packages/cartopy/img_transform.py:20[0m
[1;32m     18[0m         [38;5;28;01mfrom[39;00m [38;5;21;01mscipy[39;00m[38;5;21;01m.[39;00m[38;5;21;01mspatial[39;00m [38;5;28;01mimport[39;00m cKDTree [38;5;28;01mas[39;00m _kdtreeClass
[1;32m     19[0m     [38;5;28;01mexcept[39;00m [38;5;167;01mImportError[39;00m [38;5;28;01mas[39;00m e:
[0;32m---> 20[0m         [38;5;28;01mraise[39;00m [38;5;167;01mImportError[39;00m([38;5;124m"[39m[38;5;124mUsing image transforms requires either [39m[38;5;124m"[39m
[1;32m     21[0m                           [38;5;124m"[39m[38;5;124mpykdtree or scipy.[39m[38;5;124m"[39m) [38;5;28;01mfrom[39;00m [38;5;21;01me[39;00m
[1;32m     22[0m     _is_pykdtree [38;5;241m=[39m [38;5;28;01mFalse[39;00m
[1;32m     24[0m [38;5;28;01mimport[39;00m [38;5;21;01mcartopy[39;00m[38;5;21;01m.[39;00m[38;5;21;01mcrs[39;00m [38;5;28;01mas[39;00m [38;5;21;01mccrs[39;00m

[0;31mImportError[0m: Using image transforms requires either pykdtree or scipy.

