Traceback (most recent call last):
  File "/Users/shakidi/opt/anaconda3/envs/myenv/lib/python3.9/site-packages/jupyter_cache/executors/utils.py", line 58, in single_nb_execution
    executenb(
  File "/Users/shakidi/opt/anaconda3/envs/myenv/lib/python3.9/site-packages/nbclient/client.py", line 1305, in execute
    return NotebookClient(nb=nb, resources=resources, km=km, **kwargs).execute()
  File "/Users/shakidi/opt/anaconda3/envs/myenv/lib/python3.9/site-packages/jupyter_core/utils/__init__.py", line 173, in wrapped
    return loop.run_until_complete(inner)
  File "/Users/shakidi/opt/anaconda3/envs/myenv/lib/python3.9/asyncio/base_events.py", line 647, in run_until_complete
    return future.result()
  File "/Users/shakidi/opt/anaconda3/envs/myenv/lib/python3.9/site-packages/nbclient/client.py", line 705, in async_execute
    await self.async_execute_cell(
  File "/Users/shakidi/opt/anaconda3/envs/myenv/lib/python3.9/site-packages/nbclient/client.py", line 1058, in async_execute_cell
    await self._check_raise_for_error(cell, cell_index, exec_reply)
  File "/Users/shakidi/opt/anaconda3/envs/myenv/lib/python3.9/site-packages/nbclient/client.py", line 914, in _check_raise_for_error
    raise CellExecutionError.from_cell_and_msg(cell, exec_reply_content)
nbclient.exceptions.CellExecutionError: An error occurred while executing the following cell:
------------------
___,___,___,___,___,___,___ = [np.___(___[___]) for ___ in range(___)]
------------------


[0;31m---------------------------------------------------------------------------[0m
[0;31mTypeError[0m                                 Traceback (most recent call last)
Cell [0;32mIn[4], line 1[0m
[0;32m----> 1[0m ___,___,___,___,___,___,___ [38;5;241m=[39m [np[38;5;241m.[39m___(___[___]) [38;5;28;01mfor[39;00m ___ [38;5;129;01min[39;00m [38;5;28;43mrange[39;49m[43m([49m[43m___[49m[43m)[49m]

[0;31mTypeError[0m: 'str' object cannot be interpreted as an integer

