Traceback (most recent call last):
  File "/Users/shakidi/opt/anaconda3/envs/myenv/lib/python3.9/site-packages/jupyter_cache/executors/utils.py", line 58, in single_nb_execution
    executenb(
  File "/Users/shakidi/opt/anaconda3/envs/myenv/lib/python3.9/site-packages/nbclient/client.py", line 1305, in execute
    return NotebookClient(nb=nb, resources=resources, km=km, **kwargs).execute()
  File "/Users/shakidi/opt/anaconda3/envs/myenv/lib/python3.9/site-packages/jupyter_core/utils/__init__.py", line 173, in wrapped
    return loop.run_until_complete(inner)
  File "/Users/shakidi/opt/anaconda3/envs/myenv/lib/python3.9/asyncio/base_events.py", line 647, in run_until_complete
    return future.result()
  File "/Users/shakidi/opt/anaconda3/envs/myenv/lib/python3.9/site-packages/nbclient/client.py", line 705, in async_execute
    await self.async_execute_cell(
  File "/Users/shakidi/opt/anaconda3/envs/myenv/lib/python3.9/site-packages/nbclient/client.py", line 1058, in async_execute_cell
    await self._check_raise_for_error(cell, cell_index, exec_reply)
  File "/Users/shakidi/opt/anaconda3/envs/myenv/lib/python3.9/site-packages/nbclient/client.py", line 914, in _check_raise_for_error
    raise CellExecutionError.from_cell_and_msg(cell, exec_reply_content)
nbclient.exceptions.CellExecutionError: An error occurred while executing the following cell:
------------------
# √âcrivez votre classe ici
classe planet :
  def __init__(____,inname=____,inmass=____):
    self.name = inname
    self.mass = inmass
# Cr√©er une nouvelle instance de cette classe pour repr√©senter la Terre (masse=5,97)
terre = planet(_______,_____)
# Cr√©er une nouvelle instance de cette classe pour repr√©senter Jupiter (masse=1898)
jupiter = planet(_______,____)
------------------


[0;36m  Cell [0;32mIn[1], line 2[0;36m[0m
[0;31m    classe planet :[0m
[0m           ^[0m
[0;31mSyntaxError[0m[0;31m:[0m invalid syntax


